Workbook

Sheet MapCharts

Sheet ChartData
A1: Country | B1: Count | C1: Average Salary
A2: {=_xlfn._xlws.SORT(_xlfn.UNIQUE(Data!$B$2:$B$32675),1,1,FALSE)} -> Albania | B2: =COUNTIF(Data!$B$2:$B$32673,$A2) -> 5 | C2: {=IFERROR(MEDIAN(IF((Data!$B$2:$B$32673=ChartData!$A2)*(Data!$C$2:$C$32673<>""), Data!$C$2:$C$32673)), "")} -> 69963
A3: Algeria | B3: =COUNTIF(Data!$B$2:$B$32673,$A3) -> 4 | C3: {=IFERROR(MEDIAN(IF((Data!$B$2:$B$32673=ChartData!$A3)*(Data!$C$2:$C$32673<>""), Data!$C$2:$C$32673)), "")} -> 44550
A4: Argentina | B4: =COUNTIF(Data!$B$2:$B$32673,$A4) -> 36 | C4: {=IFERROR(MEDIAN(IF((Data!$B$2:$B$32673=ChartData!$A4)*(Data!$C$2:$C$32673<>""), Data!$C$2:$C$32673)), "")} -> 97528
A5: Armenia | B5: =COUNTIF(Data!$B$2:$B$32673,$A5) -> 5 | C5: {=IFERROR(MEDIAN(IF((Data!$B$2:$B$32673=ChartData!$A5)*(Data!$C$2:$C$32673<>""), Data!$C$2:$C$32673)), "")} -> 100500
A6: Australia | B6: =COUNTIF(Data!$B$2:$B$32673,$A6) -> 156 | C6: {=IFERROR(MEDIAN(IF((Data!$B$2:$B$32673=ChartData!$A6)*(Data!$C$2:$C$32673<>""), Data!$C$2:$C$32673)), "")} -> 118500
A7: Austria | B7: =COUNTIF(Data!$B$2:$B$32673,$A7) -> 19 | C7: {=IFERROR(MEDIAN(IF((Data!$B$2:$B$32673=ChartData!$A7)*(Data!$C$2:$C$32673<>""), Data!$C$2:$C$32673)), "")} -> 89100
A8: Azerbaijan | B8: =COUNTIF(Data!$B$2:$B$32673,$A8) -> 1 | C8: {=IFERROR(MEDIAN(IF((Data!$B$2:$B$32673=ChartData!$A8)*(Data!$C$2:$C$32673<>""), Data!$C$2:$C$32673)), "")} -> 30750
A9: Bahamas | B9: =COUNTIF(Data!$B$2:$B$32673,$A9) -> 22 | C9: {=IFERROR(MEDIAN(IF((Data!$B$2:$B$32673=ChartData!$A9)*(Data!$C$2:$C$32673<>""), Data!$C$2:$C$32673)), "")} -> 208114
A10: Bangladesh | B10: =COUNTIF(Data!$B$2:$B$32673,$A10) -> 3 | C10: {=IFERROR(MEDIAN(IF((Data!$B$2:$B$32673=ChartData!$A10)*(Data!$C$2:$C$32673<>""), Data!$C$2:$C$32673)), "")} -> 69000
A11: Belarus | B11: =COUNTIF(Data!$B$2:$B$32673,$A11) -> 2 | C11: {=IFERROR(MEDIAN(IF((Data!$B$2:$B$32673=ChartData!$A11)*(Data!$C$2:$C$32673<>""), Data!$C$2:$C$32673)), "")} -> 400000
A12: Belgium | B12: =COUNTIF(Data!$B$2:$B$32673,$A12) -> 58 | C12: {=IFERROR(MEDIAN(IF((Data!$B$2:$B$32673=ChartData!$A12)*(Data!$C$2:$C$32673<>""), Data!$C$2:$C$32673)), "")} -> 89100
A13: Benin | B13: =COUNTIF(Data!$B$2:$B$32673,$A13) -> 1 | C13: {=IFERROR(MEDIAN(IF((Data!$B$2:$B$32673=ChartData!$A13)*(Data!$C$2:$C$32673<>""), Data!$C$2:$C$32673)), "")}
A14: Bolivia | B14: =COUNTIF(Data!$B$2:$B$32673,$A14) -> 2 | C14: {=IFERROR(MEDIAN(IF((Data!$B$2:$B$32673=ChartData!$A14)*(Data!$C$2:$C$32673<>""), Data!$C$2:$C$32673)), "")}
... A92: South Korea | B92: =COUNTIF(Data!$B$2:$B$32673,$A92) -> 65 | C92: {=IFERROR(MEDIAN(IF((Data!$B$2:$B$32673=ChartData!$A92)*(Data!$C$2:$C$32673<>""), Data!$C$2:$C$32673)), "")} -> 111175
A93: Spain | B93: =COUNTIF(Data!$B$2:$B$32673,$A93) -> 149 | C93: {=IFERROR(MEDIAN(IF((Data!$B$2:$B$32673=ChartData!$A93)*(Data!$C$2:$C$32673<>""), Data!$C$2:$C$32673)), "")} -> 98500 | D93: =MAX(C2:C112) -> 400000
A94: Sri Lanka | B94: =COUNTIF(Data!$B$2:$B$32673,$A94) -> 17 | C94: {=IFERROR(MEDIAN(IF((Data!$B$2:$B$32673=ChartData!$A94)*(Data!$C$2:$C$32673<>""), Data!$C$2:$C$32673)), "")} -> 98500
A95: Sudan | B95: =COUNTIF(Data!$B$2:$B$32673,$A95) -> 2680 | C95: {=IFERROR(MEDIAN(IF((Data!$B$2:$B$32673=ChartData!$A95)*(Data!$C$2:$C$32673<>""), Data!$C$2:$C$32673)), "")} -> 127500
A96: Sweden | B96: =COUNTIF(Data!$B$2:$B$32673,$A96) -> 47 | C96: {=IFERROR(MEDIAN(IF((Data!$B$2:$B$32673=ChartData!$A96)*(Data!$C$2:$C$32673<>""), Data!$C$2:$C$32673)), "")} -> 118140
A97: Switzerland | B97: =COUNTIF(Data!$B$2:$B$32673,$A97) -> 54 | C97: {=IFERROR(MEDIAN(IF((Data!$B$2:$B$32673=ChartData!$A97)*(Data!$C$2:$C$32673<>""), Data!$C$2:$C$32673)), "")} -> 89100
A98: Taiwan | B98: =COUNTIF(Data!$B$2:$B$32673,$A98) -> 30 | C98: {=IFERROR(MEDIAN(IF((Data!$B$2:$B$32673=ChartData!$A98)*(Data!$C$2:$C$32673<>""), Data!$C$2:$C$32673)), "")} -> 79200
A99: Thailand | B99: =COUNTIF(Data!$B$2:$B$32673,$A99) -> 54 | C99: {=IFERROR(MEDIAN(IF((Data!$B$2:$B$32673=ChartData!$A99)*(Data!$C$2:$C$32673<>""), Data!$C$2:$C$32673)), "")} -> 96761
A100: Tunisia | B100: =COUNTIF(Data!$B$2:$B$32673,$A100) -> 5 | C100: {=IFERROR(MEDIAN(IF((Data!$B$2:$B$32673=ChartData!$A100)*(Data!$C$2:$C$32673<>""), Data!$C$2:$C$32673)), "")} -> 147500
A101: Turkey | B101: =COUNTIF(Data!$B$2:$B$32673,$A101) -> 24 | C101: {=IFERROR(MEDIAN(IF((Data!$B$2:$B$32673=ChartData!$A101)*(Data!$C$2:$C$32673<>""), Data!$C$2:$C$32673)), "")} -> 79200
A102: U.S. Virgin Islands | B102: =COUNTIF(Data!$B$2:$B$32673,$A102) -> 8 | C102: {=IFERROR(MEDIAN(IF((Data!$B$2:$B$32673=ChartData!$A102)*(Data!$C$2:$C$32673<>""), Data!$C$2:$C$32673)), "")} -> 125000
A103: Uganda | B103: =COUNTIF(Data!$B$2:$B$32673,$A103) -> 3 | C103: {=IFERROR(MEDIAN(IF((Data!$B$2:$B$32673=ChartData!$A103)*(Data!$C$2:$C$32673<>""), Data!$C$2:$C$32673)), "")} -> 69300
A104: Ukraine | B104: =COUNTIF(Data!$B$2:$B$32673,$A104) -> 32 | C104: {=IFERROR(MEDIAN(IF((Data!$B$2:$B$32673=ChartData!$A104)*(Data!$C$2:$C$32673<>""), Data!$C$2:$C$32673)), "")} -> 89100
A105: United Arab Emirates | B105: =COUNTIF(Data!$B$2:$B$32673,$A105) -> 26 | C105: {=IFERROR(MEDIAN(IF((Data!$B$2:$B$32673=ChartData!$A105)*(Data!$C$2:$C$32673<>""), Data!$C$2:$C$32673)), "")} -> 97528
... A112: Zimbabwe | B112: =COUNTIF(Data!$B$2:$B$32673,$A112) -> 4 | C112: {=IFERROR(MEDIAN(IF((Data!$B$2:$B$32673=ChartData!$A112)*(Data!$C$2:$C$32673<>""), Data!$C$2:$C$32673)), "")} -> 63000
A113: 0 | C113: {=IFERROR(MEDIAN(IF((Data!$B$2:$B$32673=ChartData!$A113)*(Data!$C$2:$C$32673<>""), Data!$C$2:$C$32673)), "")}

Sheet Data
A1: job_title_short | B1: job_country | C1: salary_year_avg | D1: salary_hour_avg
A2: Senior Data Scientist | B2: Sudan | C2: 128050
A3: Data Engineer | B3: United States | C3: 140000
A4: Senior Data Analyst | B4: United States | C4: 156000
A5: Machine Learning Engineer | B5: United States | C5: 140000
A6: Data Scientist | B6: United States | D6: 39.8
A7: Data Engineer | B7: Sudan | D7: 61.16
A8: Data Engineer | B8: United States | C8: 135000
A9: Senior Data Engineer | B9: United States | C9: 120000
A10: Senior Data Analyst | B10: United States | C10: 170000
A11: Data Scientist | B11: United States | C11: 224500
A12: Data Scientist | B12: United States | D12: 53.39
A13: Data Scientist | B13: United States | C13: 225000
A14: Data Engineer | B14: United States | D14: 64.44
A15: Data Scientist | B15: United States | C15: 157500
A16: Data Analyst | B16: United States | C16: 149509
A17: Data Scientist | B17: United States | D17: 55
A18: Data Engineer | B18: United States | C18: 112500
A19: Data Engineer | B19: United States | C19: 115000
A20: Data Scientist | B20: United States | C20: 98902
A21: Senior Data Engineer | B21: United States | C21: 173500
A22: Data Analyst | B22: United States | D22: 15
A23: Data Scientist | B23: France | C23: 88128
A24: Senior Data Scientist | B24: United States | C24: 170000
A25: Data Engineer | B25: United States | D25: 42.5
A26: Data Scientist | B26: United States | C26: 125000
A27: Data Engineer | B27: United States | D27: 64.44
A28: Senior Data Engineer | B28: Sudan | C28: 260775
A29: Senior Data Engineer | B29: United States | D29: 69
A30: Senior Data Engineer | B30: United States | C30: 125000
A31: Data Scientist | B31: United States | D31: 24
A32: Data Analyst | B32: United States | C32: 125000
A33: Data Scientist | B33: United States | D33: 25
A34: Data Engineer | B34: United States | C34: 97500
A35: Senior Data Engineer | B35: United States | C35: 147500
A36: Data Analyst | B36: United States | C36: 84000
A37: Data Engineer | B37: United States | D37: 61.16
A38: Data Scientist | B38: United States | C38: 105800
A39: Data Engineer | B39: United States | D39: 55
A40: Senior Data Engineer | B40: United States | C40: 160000
...
